{"level":"ERROR","location":"[__symbol_conversion:1352] data_ws","message":{"code":-300,"message":"Please provide a valid symbol","s":"error","type":"sub","invalid_symbols":["NSE: NIFTY28OCTFUT"]},"timestamp":"2024-11-05 13:52:16,034+0530","service":"FyersDataSocket"}
{"level":"ERROR","location":"[__symbol_conversion:1352] data_ws","message":{"code":-300,"message":"Please provide a valid symbol","s":"error","type":"sub","invalid_symbols":["NSE: NIFTY28NOVFUT"]},"timestamp":"2024-11-05 13:52:58,275+0530","service":"FyersDataSocket"}
{"level":"ERROR","location":"[__symbol_conversion:1352] data_ws","message":{"code":-300,"message":"Please provide a valid symbol","s":"error","type":"sub","invalid_symbols":["NSE:NIFTY28NOVFUT"]},"timestamp":"2024-11-05 13:53:23,092+0530","service":"FyersDataSocket"}
{"level":"ERROR","location":"[__symbol_conversion:1352] data_ws","message":{"code":-300,"message":"Please provide a valid symbol","s":"error","type":"sub","invalid_symbols":["NSE:NIFTY28NOVFUT","NSE:BANKNIFTY27NOVFUT"]},"timestamp":"2024-11-05 13:55:05,769+0530","service":"FyersDataSocket"}
{"level":"ERROR","location":"[<lambda>:1663] data_ws","message":"Connection to remote host was lost.","timestamp":"2024-11-06 16:54:40,011+0530","service":"FyersDataSocket"}
{"level":"ERROR","location":"[__symbol_conversion:1352] data_ws","message":{"code":-300,"message":"Please provide a valid symbol","s":"error","type":"sub","invalid_symbols":["NSE:NIFTY"]},"timestamp":"2024-11-08 17:09:56,794+0530","service":"FyersDataSocket"}
{"level":"ERROR","location":"[<lambda>:1663] data_ws","message":"Connection to remote host was lost.","timestamp":"2024-11-08 17:40:14,800+0530","service":"FyersDataSocket"}
{"level":"ERROR","location":"[<lambda>:1663] data_ws","message":"[Errno 11001] getaddrinfo failed","timestamp":"2024-11-08 17:40:19,810+0530","service":"FyersDataSocket"}
{"level":"ERROR","location":"[symbol_to_hsmtoken:126] data_ws","message":"HTTPSConnectionPool(host='api-t1.fyers.in', port=443): Max retries exceeded with url: /data/symbol-token (Caused by NameResolutionError(\"<urllib3.connection.HTTPSConnection object at 0x000001C99D559790>: Failed to resolve 'api-t1.fyers.in' ([Errno 11001] getaddrinfo failed)\"))","timestamp":"2024-11-08 17:40:21,841+0530","service":"FyersDataSocket","exception":"Traceback (most recent call last):\n  File \"D:\\Desktop\\python projects\\AlgoFoxLadderStrategy\\.venv\\Lib\\site-packages\\websocket\\_app.py\", line 428, in setSock\n    dispatcher.read(self.sock.sock, read, check)\n  File \"D:\\Desktop\\python projects\\AlgoFoxLadderStrategy\\.venv\\Lib\\site-packages\\websocket\\_app.py\", line 99, in read\n    if not read_callback():\n           ^^^^^^^^^^^^^^^\n  File \"D:\\Desktop\\python projects\\AlgoFoxLadderStrategy\\.venv\\Lib\\site-packages\\websocket\\_app.py\", line 442, in read\n    raise e\n  File \"D:\\Desktop\\python projects\\AlgoFoxLadderStrategy\\.venv\\Lib\\site-packages\\websocket\\_app.py\", line 437, in read\n    op_code, frame = self.sock.recv_data_frame(True)\n                     ^^^^^^^^^^^^^^^^^^^^^^^^^^^^^^^\n  File \"D:\\Desktop\\python projects\\AlgoFoxLadderStrategy\\.venv\\Lib\\site-packages\\websocket\\_core.py\", line 406, in recv_data_frame\n    frame = self.recv_frame()\n            ^^^^^^^^^^^^^^^^^\n  File \"D:\\Desktop\\python projects\\AlgoFoxLadderStrategy\\.venv\\Lib\\site-packages\\websocket\\_core.py\", line 445, in recv_frame\n    return self.frame_buffer.recv_frame()\n           ^^^^^^^^^^^^^^^^^^^^^^^^^^^^^^\n  File \"D:\\Desktop\\python projects\\AlgoFoxLadderStrategy\\.venv\\Lib\\site-packages\\websocket\\_abnf.py\", line 338, in recv_frame\n    self.recv_header()\n  File \"D:\\Desktop\\python projects\\AlgoFoxLadderStrategy\\.venv\\Lib\\site-packages\\websocket\\_abnf.py\", line 294, in recv_header\n    header = self.recv_strict(2)\n             ^^^^^^^^^^^^^^^^^^^\n  File \"D:\\Desktop\\python projects\\AlgoFoxLadderStrategy\\.venv\\Lib\\site-packages\\websocket\\_abnf.py\", line 373, in recv_strict\n    bytes_ = self.recv(min(16384, shortage))\n             ^^^^^^^^^^^^^^^^^^^^^^^^^^^^^^^\n  File \"D:\\Desktop\\python projects\\AlgoFoxLadderStrategy\\.venv\\Lib\\site-packages\\websocket\\_core.py\", line 529, in _recv\n    return recv(self.sock, bufsize)\n           ^^^^^^^^^^^^^^^^^^^^^^^^\n  File \"D:\\Desktop\\python projects\\AlgoFoxLadderStrategy\\.venv\\Lib\\site-packages\\websocket\\_socket.py\", line 122, in recv\n    raise WebSocketConnectionClosedException(\nwebsocket._exceptions.WebSocketConnectionClosedException: Connection to remote host was lost.\n\nDuring handling of the above exception, another exception occurred:\n\nTraceback (most recent call last):\n  File \"D:\\Desktop\\python projects\\AlgoFoxLadderStrategy\\.venv\\Lib\\site-packages\\urllib3\\connection.py\", line 199, in _new_conn\n    sock = connection.create_connection(\n           ^^^^^^^^^^^^^^^^^^^^^^^^^^^^^\n  File \"D:\\Desktop\\python projects\\AlgoFoxLadderStrategy\\.venv\\Lib\\site-packages\\urllib3\\util\\connection.py\", line 60, in create_connection\n    for res in socket.getaddrinfo(host, port, family, socket.SOCK_STREAM):\n               ^^^^^^^^^^^^^^^^^^^^^^^^^^^^^^^^^^^^^^^^^^^^^^^^^^^^^^^^^^\n  File \"C:\\Users\\pulki\\AppData\\Local\\Programs\\Python\\Python311\\Lib\\socket.py\", line 962, in getaddrinfo\n    for res in _socket.getaddrinfo(host, port, family, type, proto, flags):\n               ^^^^^^^^^^^^^^^^^^^^^^^^^^^^^^^^^^^^^^^^^^^^^^^^^^^^^^^^^^^\nsocket.gaierror: [Errno 11001] getaddrinfo failed\n\nThe above exception was the direct cause of the following exception:\n\nTraceback (most recent call last):\n  File \"D:\\Desktop\\python projects\\AlgoFoxLadderStrategy\\.venv\\Lib\\site-packages\\urllib3\\connectionpool.py\", line 789, in urlopen\n    response = self._make_request(\n               ^^^^^^^^^^^^^^^^^^^\n  File \"D:\\Desktop\\python projects\\AlgoFoxLadderStrategy\\.venv\\Lib\\site-packages\\urllib3\\connectionpool.py\", line 490, in _make_request\n    raise new_e\n  File \"D:\\Desktop\\python projects\\AlgoFoxLadderStrategy\\.venv\\Lib\\site-packages\\urllib3\\connectionpool.py\", line 466, in _make_request\n    self._validate_conn(conn)\n  File \"D:\\Desktop\\python projects\\AlgoFoxLadderStrategy\\.venv\\Lib\\site-packages\\urllib3\\connectionpool.py\", line 1095, in _validate_conn\n    conn.connect()\n  File \"D:\\Desktop\\python projects\\AlgoFoxLadderStrategy\\.venv\\Lib\\site-packages\\urllib3\\connection.py\", line 693, in connect\n    self.sock = sock = self._new_conn()\n                       ^^^^^^^^^^^^^^^^\n  File \"D:\\Desktop\\python projects\\AlgoFoxLadderStrategy\\.venv\\Lib\\site-packages\\urllib3\\connection.py\", line 206, in _new_conn\n    raise NameResolutionError(self.host, self, e) from e\nurllib3.exceptions.NameResolutionError: <urllib3.connection.HTTPSConnection object at 0x000001C99D559790>: Failed to resolve 'api-t1.fyers.in' ([Errno 11001] getaddrinfo failed)\n\nThe above exception was the direct cause of the following exception:\n\nTraceback (most recent call last):\n  File \"D:\\Desktop\\python projects\\AlgoFoxLadderStrategy\\.venv\\Lib\\site-packages\\requests\\adapters.py\", line 486, in send\n    resp = conn.urlopen(\n           ^^^^^^^^^^^^^\n  File \"D:\\Desktop\\python projects\\AlgoFoxLadderStrategy\\.venv\\Lib\\site-packages\\urllib3\\connectionpool.py\", line 843, in urlopen\n    retries = retries.increment(\n              ^^^^^^^^^^^^^^^^^^\n  File \"D:\\Desktop\\python projects\\AlgoFoxLadderStrategy\\.venv\\Lib\\site-packages\\urllib3\\util\\retry.py\", line 519, in increment\n    raise MaxRetryError(_pool, url, reason) from reason  # type: ignore[arg-type]\n    ^^^^^^^^^^^^^^^^^^^^^^^^^^^^^^^^^^^^^^^^^^^^^^^^^^^\nurllib3.exceptions.MaxRetryError: HTTPSConnectionPool(host='api-t1.fyers.in', port=443): Max retries exceeded with url: /data/symbol-token (Caused by NameResolutionError(\"<urllib3.connection.HTTPSConnection object at 0x000001C99D559790>: Failed to resolve 'api-t1.fyers.in' ([Errno 11001] getaddrinfo failed)\"))\n\nDuring handling of the above exception, another exception occurred:\n\nTraceback (most recent call last):\n  File \"D:\\Desktop\\python projects\\AlgoFoxLadderStrategy\\.venv\\Lib\\site-packages\\fyers_apiv3\\FyersWebsocket\\data_ws.py\", line 63, in symbol_to_hsmtoken\n    response = requests.post(\n               ^^^^^^^^^^^^^^\n  File \"D:\\Desktop\\python projects\\AlgoFoxLadderStrategy\\.venv\\Lib\\site-packages\\requests\\api.py\", line 115, in post\n    return request(\"post\", url, data=data, json=json, **kwargs)\n           ^^^^^^^^^^^^^^^^^^^^^^^^^^^^^^^^^^^^^^^^^^^^^^^^^^^^\n  File \"D:\\Desktop\\python projects\\AlgoFoxLadderStrategy\\.venv\\Lib\\site-packages\\requests\\api.py\", line 59, in request\n    return session.request(method=method, url=url, **kwargs)\n           ^^^^^^^^^^^^^^^^^^^^^^^^^^^^^^^^^^^^^^^^^^^^^^^^^\n  File \"D:\\Desktop\\python projects\\AlgoFoxLadderStrategy\\.venv\\Lib\\site-packages\\requests\\sessions.py\", line 589, in request\n    resp = self.send(prep, **send_kwargs)\n           ^^^^^^^^^^^^^^^^^^^^^^^^^^^^^^\n  File \"D:\\Desktop\\python projects\\AlgoFoxLadderStrategy\\.venv\\Lib\\site-packages\\requests\\sessions.py\", line 703, in send\n    r = adapter.send(request, **kwargs)\n        ^^^^^^^^^^^^^^^^^^^^^^^^^^^^^^^\n  File \"D:\\Desktop\\python projects\\AlgoFoxLadderStrategy\\.venv\\Lib\\site-packages\\requests\\adapters.py\", line 519, in send\n    raise ConnectionError(e, request=request)\nrequests.exceptions.ConnectionError: HTTPSConnectionPool(host='api-t1.fyers.in', port=443): Max retries exceeded with url: /data/symbol-token (Caused by NameResolutionError(\"<urllib3.connection.HTTPSConnection object at 0x000001C99D559790>: Failed to resolve 'api-t1.fyers.in' ([Errno 11001] getaddrinfo failed)\"))","exception_name":"ConnectionError"}
{"level":"ERROR","location":"[__symbol_conversion:1374] data_ws","message":"'NoneType' object is not subscriptable","timestamp":"2024-11-08 17:40:22,242+0530","service":"FyersDataSocket","exception":"Traceback (most recent call last):\n  File \"D:\\Desktop\\python projects\\AlgoFoxLadderStrategy\\.venv\\Lib\\site-packages\\websocket\\_app.py\", line 428, in setSock\n    dispatcher.read(self.sock.sock, read, check)\n  File \"D:\\Desktop\\python projects\\AlgoFoxLadderStrategy\\.venv\\Lib\\site-packages\\websocket\\_app.py\", line 99, in read\n    if not read_callback():\n           ^^^^^^^^^^^^^^^\n  File \"D:\\Desktop\\python projects\\AlgoFoxLadderStrategy\\.venv\\Lib\\site-packages\\websocket\\_app.py\", line 442, in read\n    raise e\n  File \"D:\\Desktop\\python projects\\AlgoFoxLadderStrategy\\.venv\\Lib\\site-packages\\websocket\\_app.py\", line 437, in read\n    op_code, frame = self.sock.recv_data_frame(True)\n                     ^^^^^^^^^^^^^^^^^^^^^^^^^^^^^^^\n  File \"D:\\Desktop\\python projects\\AlgoFoxLadderStrategy\\.venv\\Lib\\site-packages\\websocket\\_core.py\", line 406, in recv_data_frame\n    frame = self.recv_frame()\n            ^^^^^^^^^^^^^^^^^\n  File \"D:\\Desktop\\python projects\\AlgoFoxLadderStrategy\\.venv\\Lib\\site-packages\\websocket\\_core.py\", line 445, in recv_frame\n    return self.frame_buffer.recv_frame()\n           ^^^^^^^^^^^^^^^^^^^^^^^^^^^^^^\n  File \"D:\\Desktop\\python projects\\AlgoFoxLadderStrategy\\.venv\\Lib\\site-packages\\websocket\\_abnf.py\", line 338, in recv_frame\n    self.recv_header()\n  File \"D:\\Desktop\\python projects\\AlgoFoxLadderStrategy\\.venv\\Lib\\site-packages\\websocket\\_abnf.py\", line 294, in recv_header\n    header = self.recv_strict(2)\n             ^^^^^^^^^^^^^^^^^^^\n  File \"D:\\Desktop\\python projects\\AlgoFoxLadderStrategy\\.venv\\Lib\\site-packages\\websocket\\_abnf.py\", line 373, in recv_strict\n    bytes_ = self.recv(min(16384, shortage))\n             ^^^^^^^^^^^^^^^^^^^^^^^^^^^^^^^\n  File \"D:\\Desktop\\python projects\\AlgoFoxLadderStrategy\\.venv\\Lib\\site-packages\\websocket\\_core.py\", line 529, in _recv\n    return recv(self.sock, bufsize)\n           ^^^^^^^^^^^^^^^^^^^^^^^^\n  File \"D:\\Desktop\\python projects\\AlgoFoxLadderStrategy\\.venv\\Lib\\site-packages\\websocket\\_socket.py\", line 122, in recv\n    raise WebSocketConnectionClosedException(\nwebsocket._exceptions.WebSocketConnectionClosedException: Connection to remote host was lost.\n\nDuring handling of the above exception, another exception occurred:\n\nTraceback (most recent call last):\n  File \"D:\\Desktop\\python projects\\AlgoFoxLadderStrategy\\.venv\\Lib\\site-packages\\fyers_apiv3\\FyersWebsocket\\data_ws.py\", line 1333, in __symbol_conversion\n    if symbol_value[3] != \"\":\n       ~~~~~~~~~~~~^^^\nTypeError: 'NoneType' object is not subscriptable","exception_name":"TypeError"}
{"level":"ERROR","location":"[<lambda>:1663] data_ws","message":"[Errno 11001] getaddrinfo failed","timestamp":"2024-11-08 17:40:24,921+0530","service":"FyersDataSocket"}
{"level":"ERROR","location":"[symbol_to_hsmtoken:126] data_ws","message":"HTTPSConnectionPool(host='api-t1.fyers.in', port=443): Max retries exceeded with url: /data/symbol-token (Caused by NameResolutionError(\"<urllib3.connection.HTTPSConnection object at 0x000001C99D546F10>: Failed to resolve 'api-t1.fyers.in' ([Errno 11001] getaddrinfo failed)\"))","timestamp":"2024-11-08 17:40:26,842+0530","service":"FyersDataSocket","exception":"Traceback (most recent call last):\n  File \"D:\\Desktop\\python projects\\AlgoFoxLadderStrategy\\.venv\\Lib\\site-packages\\websocket\\_http.py\", line 155, in _get_addrinfo_list\n    addrinfo_list = socket.getaddrinfo(\n                    ^^^^^^^^^^^^^^^^^^^\n  File \"C:\\Users\\pulki\\AppData\\Local\\Programs\\Python\\Python311\\Lib\\socket.py\", line 962, in getaddrinfo\n    for res in _socket.getaddrinfo(host, port, family, type, proto, flags):\n               ^^^^^^^^^^^^^^^^^^^^^^^^^^^^^^^^^^^^^^^^^^^^^^^^^^^^^^^^^^^\nsocket.gaierror: [Errno 11001] getaddrinfo failed\n\nDuring handling of the above exception, another exception occurred:\n\nTraceback (most recent call last):\n  File \"D:\\Desktop\\python projects\\AlgoFoxLadderStrategy\\.venv\\Lib\\site-packages\\websocket\\_app.py\", line 412, in setSock\n    self.sock.connect(\n  File \"D:\\Desktop\\python projects\\AlgoFoxLadderStrategy\\.venv\\Lib\\site-packages\\websocket\\_core.py\", line 249, in connect\n    self.sock, addrs = connect(url, self.sock_opt, proxy_info(**options),\n                       ^^^^^^^^^^^^^^^^^^^^^^^^^^^^^^^^^^^^^^^^^^^^^^^^^^\n  File \"D:\\Desktop\\python projects\\AlgoFoxLadderStrategy\\.venv\\Lib\\site-packages\\websocket\\_http.py\", line 122, in connect\n    addrinfo_list, need_tunnel, auth = _get_addrinfo_list(\n                                       ^^^^^^^^^^^^^^^^^^^\n  File \"D:\\Desktop\\python projects\\AlgoFoxLadderStrategy\\.venv\\Lib\\site-packages\\websocket\\_http.py\", line 167, in _get_addrinfo_list\n    raise WebSocketAddressException(e)\nwebsocket._exceptions.WebSocketAddressException: [Errno 11001] getaddrinfo failed\n\nDuring handling of the above exception, another exception occurred:\n\nTraceback (most recent call last):\n  File \"D:\\Desktop\\python projects\\AlgoFoxLadderStrategy\\.venv\\Lib\\site-packages\\urllib3\\connection.py\", line 199, in _new_conn\n    sock = connection.create_connection(\n           ^^^^^^^^^^^^^^^^^^^^^^^^^^^^^\n  File \"D:\\Desktop\\python projects\\AlgoFoxLadderStrategy\\.venv\\Lib\\site-packages\\urllib3\\util\\connection.py\", line 60, in create_connection\n    for res in socket.getaddrinfo(host, port, family, socket.SOCK_STREAM):\n               ^^^^^^^^^^^^^^^^^^^^^^^^^^^^^^^^^^^^^^^^^^^^^^^^^^^^^^^^^^\n  File \"C:\\Users\\pulki\\AppData\\Local\\Programs\\Python\\Python311\\Lib\\socket.py\", line 962, in getaddrinfo\n    for res in _socket.getaddrinfo(host, port, family, type, proto, flags):\n               ^^^^^^^^^^^^^^^^^^^^^^^^^^^^^^^^^^^^^^^^^^^^^^^^^^^^^^^^^^^\nsocket.gaierror: [Errno 11001] getaddrinfo failed\n\nThe above exception was the direct cause of the following exception:\n\nTraceback (most recent call last):\n  File \"D:\\Desktop\\python projects\\AlgoFoxLadderStrategy\\.venv\\Lib\\site-packages\\urllib3\\connectionpool.py\", line 789, in urlopen\n    response = self._make_request(\n               ^^^^^^^^^^^^^^^^^^^\n  File \"D:\\Desktop\\python projects\\AlgoFoxLadderStrategy\\.venv\\Lib\\site-packages\\urllib3\\connectionpool.py\", line 490, in _make_request\n    raise new_e\n  File \"D:\\Desktop\\python projects\\AlgoFoxLadderStrategy\\.venv\\Lib\\site-packages\\urllib3\\connectionpool.py\", line 466, in _make_request\n    self._validate_conn(conn)\n  File \"D:\\Desktop\\python projects\\AlgoFoxLadderStrategy\\.venv\\Lib\\site-packages\\urllib3\\connectionpool.py\", line 1095, in _validate_conn\n    conn.connect()\n  File \"D:\\Desktop\\python projects\\AlgoFoxLadderStrategy\\.venv\\Lib\\site-packages\\urllib3\\connection.py\", line 693, in connect\n    self.sock = sock = self._new_conn()\n                       ^^^^^^^^^^^^^^^^\n  File \"D:\\Desktop\\python projects\\AlgoFoxLadderStrategy\\.venv\\Lib\\site-packages\\urllib3\\connection.py\", line 206, in _new_conn\n    raise NameResolutionError(self.host, self, e) from e\nurllib3.exceptions.NameResolutionError: <urllib3.connection.HTTPSConnection object at 0x000001C99D546F10>: Failed to resolve 'api-t1.fyers.in' ([Errno 11001] getaddrinfo failed)\n\nThe above exception was the direct cause of the following exception:\n\nTraceback (most recent call last):\n  File \"D:\\Desktop\\python projects\\AlgoFoxLadderStrategy\\.venv\\Lib\\site-packages\\requests\\adapters.py\", line 486, in send\n    resp = conn.urlopen(\n           ^^^^^^^^^^^^^\n  File \"D:\\Desktop\\python projects\\AlgoFoxLadderStrategy\\.venv\\Lib\\site-packages\\urllib3\\connectionpool.py\", line 843, in urlopen\n    retries = retries.increment(\n              ^^^^^^^^^^^^^^^^^^\n  File \"D:\\Desktop\\python projects\\AlgoFoxLadderStrategy\\.venv\\Lib\\site-packages\\urllib3\\util\\retry.py\", line 519, in increment\n    raise MaxRetryError(_pool, url, reason) from reason  # type: ignore[arg-type]\n    ^^^^^^^^^^^^^^^^^^^^^^^^^^^^^^^^^^^^^^^^^^^^^^^^^^^\nurllib3.exceptions.MaxRetryError: HTTPSConnectionPool(host='api-t1.fyers.in', port=443): Max retries exceeded with url: /data/symbol-token (Caused by NameResolutionError(\"<urllib3.connection.HTTPSConnection object at 0x000001C99D546F10>: Failed to resolve 'api-t1.fyers.in' ([Errno 11001] getaddrinfo failed)\"))\n\nDuring handling of the above exception, another exception occurred:\n\nTraceback (most recent call last):\n  File \"D:\\Desktop\\python projects\\AlgoFoxLadderStrategy\\.venv\\Lib\\site-packages\\fyers_apiv3\\FyersWebsocket\\data_ws.py\", line 63, in symbol_to_hsmtoken\n    response = requests.post(\n               ^^^^^^^^^^^^^^\n  File \"D:\\Desktop\\python projects\\AlgoFoxLadderStrategy\\.venv\\Lib\\site-packages\\requests\\api.py\", line 115, in post\n    return request(\"post\", url, data=data, json=json, **kwargs)\n           ^^^^^^^^^^^^^^^^^^^^^^^^^^^^^^^^^^^^^^^^^^^^^^^^^^^^\n  File \"D:\\Desktop\\python projects\\AlgoFoxLadderStrategy\\.venv\\Lib\\site-packages\\requests\\api.py\", line 59, in request\n    return session.request(method=method, url=url, **kwargs)\n           ^^^^^^^^^^^^^^^^^^^^^^^^^^^^^^^^^^^^^^^^^^^^^^^^^\n  File \"D:\\Desktop\\python projects\\AlgoFoxLadderStrategy\\.venv\\Lib\\site-packages\\requests\\sessions.py\", line 589, in request\n    resp = self.send(prep, **send_kwargs)\n           ^^^^^^^^^^^^^^^^^^^^^^^^^^^^^^\n  File \"D:\\Desktop\\python projects\\AlgoFoxLadderStrategy\\.venv\\Lib\\site-packages\\requests\\sessions.py\", line 703, in send\n    r = adapter.send(request, **kwargs)\n        ^^^^^^^^^^^^^^^^^^^^^^^^^^^^^^^\n  File \"D:\\Desktop\\python projects\\AlgoFoxLadderStrategy\\.venv\\Lib\\site-packages\\requests\\adapters.py\", line 519, in send\n    raise ConnectionError(e, request=request)\nrequests.exceptions.ConnectionError: HTTPSConnectionPool(host='api-t1.fyers.in', port=443): Max retries exceeded with url: /data/symbol-token (Caused by NameResolutionError(\"<urllib3.connection.HTTPSConnection object at 0x000001C99D546F10>: Failed to resolve 'api-t1.fyers.in' ([Errno 11001] getaddrinfo failed)\"))","exception_name":"ConnectionError"}
{"level":"ERROR","location":"[__symbol_conversion:1374] data_ws","message":"'NoneType' object is not subscriptable","timestamp":"2024-11-08 17:40:26,917+0530","service":"FyersDataSocket","exception":"Traceback (most recent call last):\n  File \"D:\\Desktop\\python projects\\AlgoFoxLadderStrategy\\.venv\\Lib\\site-packages\\websocket\\_http.py\", line 155, in _get_addrinfo_list\n    addrinfo_list = socket.getaddrinfo(\n                    ^^^^^^^^^^^^^^^^^^^\n  File \"C:\\Users\\pulki\\AppData\\Local\\Programs\\Python\\Python311\\Lib\\socket.py\", line 962, in getaddrinfo\n    for res in _socket.getaddrinfo(host, port, family, type, proto, flags):\n               ^^^^^^^^^^^^^^^^^^^^^^^^^^^^^^^^^^^^^^^^^^^^^^^^^^^^^^^^^^^\nsocket.gaierror: [Errno 11001] getaddrinfo failed\n\nDuring handling of the above exception, another exception occurred:\n\nTraceback (most recent call last):\n  File \"D:\\Desktop\\python projects\\AlgoFoxLadderStrategy\\.venv\\Lib\\site-packages\\websocket\\_app.py\", line 412, in setSock\n    self.sock.connect(\n  File \"D:\\Desktop\\python projects\\AlgoFoxLadderStrategy\\.venv\\Lib\\site-packages\\websocket\\_core.py\", line 249, in connect\n    self.sock, addrs = connect(url, self.sock_opt, proxy_info(**options),\n                       ^^^^^^^^^^^^^^^^^^^^^^^^^^^^^^^^^^^^^^^^^^^^^^^^^^\n  File \"D:\\Desktop\\python projects\\AlgoFoxLadderStrategy\\.venv\\Lib\\site-packages\\websocket\\_http.py\", line 122, in connect\n    addrinfo_list, need_tunnel, auth = _get_addrinfo_list(\n                                       ^^^^^^^^^^^^^^^^^^^\n  File \"D:\\Desktop\\python projects\\AlgoFoxLadderStrategy\\.venv\\Lib\\site-packages\\websocket\\_http.py\", line 167, in _get_addrinfo_list\n    raise WebSocketAddressException(e)\nwebsocket._exceptions.WebSocketAddressException: [Errno 11001] getaddrinfo failed\n\nDuring handling of the above exception, another exception occurred:\n\nTraceback (most recent call last):\n  File \"D:\\Desktop\\python projects\\AlgoFoxLadderStrategy\\.venv\\Lib\\site-packages\\fyers_apiv3\\FyersWebsocket\\data_ws.py\", line 1333, in __symbol_conversion\n    if symbol_value[3] != \"\":\n       ~~~~~~~~~~~~^^^\nTypeError: 'NoneType' object is not subscriptable","exception_name":"TypeError"}
{"level":"ERROR","location":"[<lambda>:1663] data_ws","message":"[Errno 11001] getaddrinfo failed","timestamp":"2024-11-08 17:40:29,931+0530","service":"FyersDataSocket"}
{"level":"ERROR","location":"[symbol_to_hsmtoken:126] data_ws","message":"HTTPSConnectionPool(host='api-t1.fyers.in', port=443): Max retries exceeded with url: /data/symbol-token (Caused by NameResolutionError(\"<urllib3.connection.HTTPSConnection object at 0x000001C9CB0CF7D0>: Failed to resolve 'api-t1.fyers.in' ([Errno 11001] getaddrinfo failed)\"))","timestamp":"2024-11-08 17:40:31,962+0530","service":"FyersDataSocket","exception":"Traceback (most recent call last):\n  File \"D:\\Desktop\\python projects\\AlgoFoxLadderStrategy\\.venv\\Lib\\site-packages\\websocket\\_http.py\", line 155, in _get_addrinfo_list\n    addrinfo_list = socket.getaddrinfo(\n                    ^^^^^^^^^^^^^^^^^^^\n  File \"C:\\Users\\pulki\\AppData\\Local\\Programs\\Python\\Python311\\Lib\\socket.py\", line 962, in getaddrinfo\n    for res in _socket.getaddrinfo(host, port, family, type, proto, flags):\n               ^^^^^^^^^^^^^^^^^^^^^^^^^^^^^^^^^^^^^^^^^^^^^^^^^^^^^^^^^^^\nsocket.gaierror: [Errno 11001] getaddrinfo failed\n\nDuring handling of the above exception, another exception occurred:\n\nTraceback (most recent call last):\n  File \"D:\\Desktop\\python projects\\AlgoFoxLadderStrategy\\.venv\\Lib\\site-packages\\websocket\\_app.py\", line 412, in setSock\n    self.sock.connect(\n  File \"D:\\Desktop\\python projects\\AlgoFoxLadderStrategy\\.venv\\Lib\\site-packages\\websocket\\_core.py\", line 249, in connect\n    self.sock, addrs = connect(url, self.sock_opt, proxy_info(**options),\n                       ^^^^^^^^^^^^^^^^^^^^^^^^^^^^^^^^^^^^^^^^^^^^^^^^^^\n  File \"D:\\Desktop\\python projects\\AlgoFoxLadderStrategy\\.venv\\Lib\\site-packages\\websocket\\_http.py\", line 122, in connect\n    addrinfo_list, need_tunnel, auth = _get_addrinfo_list(\n                                       ^^^^^^^^^^^^^^^^^^^\n  File \"D:\\Desktop\\python projects\\AlgoFoxLadderStrategy\\.venv\\Lib\\site-packages\\websocket\\_http.py\", line 167, in _get_addrinfo_list\n    raise WebSocketAddressException(e)\nwebsocket._exceptions.WebSocketAddressException: [Errno 11001] getaddrinfo failed\n\nDuring handling of the above exception, another exception occurred:\n\nTraceback (most recent call last):\n  File \"D:\\Desktop\\python projects\\AlgoFoxLadderStrategy\\.venv\\Lib\\site-packages\\urllib3\\connection.py\", line 199, in _new_conn\n    sock = connection.create_connection(\n           ^^^^^^^^^^^^^^^^^^^^^^^^^^^^^\n  File \"D:\\Desktop\\python projects\\AlgoFoxLadderStrategy\\.venv\\Lib\\site-packages\\urllib3\\util\\connection.py\", line 60, in create_connection\n    for res in socket.getaddrinfo(host, port, family, socket.SOCK_STREAM):\n               ^^^^^^^^^^^^^^^^^^^^^^^^^^^^^^^^^^^^^^^^^^^^^^^^^^^^^^^^^^\n  File \"C:\\Users\\pulki\\AppData\\Local\\Programs\\Python\\Python311\\Lib\\socket.py\", line 962, in getaddrinfo\n    for res in _socket.getaddrinfo(host, port, family, type, proto, flags):\n               ^^^^^^^^^^^^^^^^^^^^^^^^^^^^^^^^^^^^^^^^^^^^^^^^^^^^^^^^^^^\nsocket.gaierror: [Errno 11001] getaddrinfo failed\n\nThe above exception was the direct cause of the following exception:\n\nTraceback (most recent call last):\n  File \"D:\\Desktop\\python projects\\AlgoFoxLadderStrategy\\.venv\\Lib\\site-packages\\urllib3\\connectionpool.py\", line 789, in urlopen\n    response = self._make_request(\n               ^^^^^^^^^^^^^^^^^^^\n  File \"D:\\Desktop\\python projects\\AlgoFoxLadderStrategy\\.venv\\Lib\\site-packages\\urllib3\\connectionpool.py\", line 490, in _make_request\n    raise new_e\n  File \"D:\\Desktop\\python projects\\AlgoFoxLadderStrategy\\.venv\\Lib\\site-packages\\urllib3\\connectionpool.py\", line 466, in _make_request\n    self._validate_conn(conn)\n  File \"D:\\Desktop\\python projects\\AlgoFoxLadderStrategy\\.venv\\Lib\\site-packages\\urllib3\\connectionpool.py\", line 1095, in _validate_conn\n    conn.connect()\n  File \"D:\\Desktop\\python projects\\AlgoFoxLadderStrategy\\.venv\\Lib\\site-packages\\urllib3\\connection.py\", line 693, in connect\n    self.sock = sock = self._new_conn()\n                       ^^^^^^^^^^^^^^^^\n  File \"D:\\Desktop\\python projects\\AlgoFoxLadderStrategy\\.venv\\Lib\\site-packages\\urllib3\\connection.py\", line 206, in _new_conn\n    raise NameResolutionError(self.host, self, e) from e\nurllib3.exceptions.NameResolutionError: <urllib3.connection.HTTPSConnection object at 0x000001C9CB0CF7D0>: Failed to resolve 'api-t1.fyers.in' ([Errno 11001] getaddrinfo failed)\n\nThe above exception was the direct cause of the following exception:\n\nTraceback (most recent call last):\n  File \"D:\\Desktop\\python projects\\AlgoFoxLadderStrategy\\.venv\\Lib\\site-packages\\requests\\adapters.py\", line 486, in send\n    resp = conn.urlopen(\n           ^^^^^^^^^^^^^\n  File \"D:\\Desktop\\python projects\\AlgoFoxLadderStrategy\\.venv\\Lib\\site-packages\\urllib3\\connectionpool.py\", line 843, in urlopen\n    retries = retries.increment(\n              ^^^^^^^^^^^^^^^^^^\n  File \"D:\\Desktop\\python projects\\AlgoFoxLadderStrategy\\.venv\\Lib\\site-packages\\urllib3\\util\\retry.py\", line 519, in increment\n    raise MaxRetryError(_pool, url, reason) from reason  # type: ignore[arg-type]\n    ^^^^^^^^^^^^^^^^^^^^^^^^^^^^^^^^^^^^^^^^^^^^^^^^^^^\nurllib3.exceptions.MaxRetryError: HTTPSConnectionPool(host='api-t1.fyers.in', port=443): Max retries exceeded with url: /data/symbol-token (Caused by NameResolutionError(\"<urllib3.connection.HTTPSConnection object at 0x000001C9CB0CF7D0>: Failed to resolve 'api-t1.fyers.in' ([Errno 11001] getaddrinfo failed)\"))\n\nDuring handling of the above exception, another exception occurred:\n\nTraceback (most recent call last):\n  File \"D:\\Desktop\\python projects\\AlgoFoxLadderStrategy\\.venv\\Lib\\site-packages\\fyers_apiv3\\FyersWebsocket\\data_ws.py\", line 63, in symbol_to_hsmtoken\n    response = requests.post(\n               ^^^^^^^^^^^^^^\n  File \"D:\\Desktop\\python projects\\AlgoFoxLadderStrategy\\.venv\\Lib\\site-packages\\requests\\api.py\", line 115, in post\n    return request(\"post\", url, data=data, json=json, **kwargs)\n           ^^^^^^^^^^^^^^^^^^^^^^^^^^^^^^^^^^^^^^^^^^^^^^^^^^^^\n  File \"D:\\Desktop\\python projects\\AlgoFoxLadderStrategy\\.venv\\Lib\\site-packages\\requests\\api.py\", line 59, in request\n    return session.request(method=method, url=url, **kwargs)\n           ^^^^^^^^^^^^^^^^^^^^^^^^^^^^^^^^^^^^^^^^^^^^^^^^^\n  File \"D:\\Desktop\\python projects\\AlgoFoxLadderStrategy\\.venv\\Lib\\site-packages\\requests\\sessions.py\", line 589, in request\n    resp = self.send(prep, **send_kwargs)\n           ^^^^^^^^^^^^^^^^^^^^^^^^^^^^^^\n  File \"D:\\Desktop\\python projects\\AlgoFoxLadderStrategy\\.venv\\Lib\\site-packages\\requests\\sessions.py\", line 703, in send\n    r = adapter.send(request, **kwargs)\n        ^^^^^^^^^^^^^^^^^^^^^^^^^^^^^^^\n  File \"D:\\Desktop\\python projects\\AlgoFoxLadderStrategy\\.venv\\Lib\\site-packages\\requests\\adapters.py\", line 519, in send\n    raise ConnectionError(e, request=request)\nrequests.exceptions.ConnectionError: HTTPSConnectionPool(host='api-t1.fyers.in', port=443): Max retries exceeded with url: /data/symbol-token (Caused by NameResolutionError(\"<urllib3.connection.HTTPSConnection object at 0x000001C9CB0CF7D0>: Failed to resolve 'api-t1.fyers.in' ([Errno 11001] getaddrinfo failed)\"))","exception_name":"ConnectionError"}
{"level":"ERROR","location":"[__symbol_conversion:1374] data_ws","message":"'NoneType' object is not subscriptable","timestamp":"2024-11-08 17:40:31,976+0530","service":"FyersDataSocket","exception":"Traceback (most recent call last):\n  File \"D:\\Desktop\\python projects\\AlgoFoxLadderStrategy\\.venv\\Lib\\site-packages\\websocket\\_http.py\", line 155, in _get_addrinfo_list\n    addrinfo_list = socket.getaddrinfo(\n                    ^^^^^^^^^^^^^^^^^^^\n  File \"C:\\Users\\pulki\\AppData\\Local\\Programs\\Python\\Python311\\Lib\\socket.py\", line 962, in getaddrinfo\n    for res in _socket.getaddrinfo(host, port, family, type, proto, flags):\n               ^^^^^^^^^^^^^^^^^^^^^^^^^^^^^^^^^^^^^^^^^^^^^^^^^^^^^^^^^^^\nsocket.gaierror: [Errno 11001] getaddrinfo failed\n\nDuring handling of the above exception, another exception occurred:\n\nTraceback (most recent call last):\n  File \"D:\\Desktop\\python projects\\AlgoFoxLadderStrategy\\.venv\\Lib\\site-packages\\websocket\\_app.py\", line 412, in setSock\n    self.sock.connect(\n  File \"D:\\Desktop\\python projects\\AlgoFoxLadderStrategy\\.venv\\Lib\\site-packages\\websocket\\_core.py\", line 249, in connect\n    self.sock, addrs = connect(url, self.sock_opt, proxy_info(**options),\n                       ^^^^^^^^^^^^^^^^^^^^^^^^^^^^^^^^^^^^^^^^^^^^^^^^^^\n  File \"D:\\Desktop\\python projects\\AlgoFoxLadderStrategy\\.venv\\Lib\\site-packages\\websocket\\_http.py\", line 122, in connect\n    addrinfo_list, need_tunnel, auth = _get_addrinfo_list(\n                                       ^^^^^^^^^^^^^^^^^^^\n  File \"D:\\Desktop\\python projects\\AlgoFoxLadderStrategy\\.venv\\Lib\\site-packages\\websocket\\_http.py\", line 167, in _get_addrinfo_list\n    raise WebSocketAddressException(e)\nwebsocket._exceptions.WebSocketAddressException: [Errno 11001] getaddrinfo failed\n\nDuring handling of the above exception, another exception occurred:\n\nTraceback (most recent call last):\n  File \"D:\\Desktop\\python projects\\AlgoFoxLadderStrategy\\.venv\\Lib\\site-packages\\fyers_apiv3\\FyersWebsocket\\data_ws.py\", line 1333, in __symbol_conversion\n    if symbol_value[3] != \"\":\n       ~~~~~~~~~~~~^^^\nTypeError: 'NoneType' object is not subscriptable","exception_name":"TypeError"}
{"level":"ERROR","location":"[<lambda>:1663] data_ws","message":"[Errno 11001] getaddrinfo failed","timestamp":"2024-11-08 17:40:34,938+0530","service":"FyersDataSocket"}
{"level":"ERROR","location":"[symbol_to_hsmtoken:126] data_ws","message":"HTTPSConnectionPool(host='api-t1.fyers.in', port=443): Max retries exceeded with url: /data/symbol-token (Caused by NameResolutionError(\"<urllib3.connection.HTTPSConnection object at 0x000001C9CB0CA450>: Failed to resolve 'api-t1.fyers.in' ([Errno 11001] getaddrinfo failed)\"))","timestamp":"2024-11-08 17:40:37,136+0530","service":"FyersDataSocket","exception":"Traceback (most recent call last):\n  File \"D:\\Desktop\\python projects\\AlgoFoxLadderStrategy\\.venv\\Lib\\site-packages\\websocket\\_http.py\", line 155, in _get_addrinfo_list\n    addrinfo_list = socket.getaddrinfo(\n                    ^^^^^^^^^^^^^^^^^^^\n  File \"C:\\Users\\pulki\\AppData\\Local\\Programs\\Python\\Python311\\Lib\\socket.py\", line 962, in getaddrinfo\n    for res in _socket.getaddrinfo(host, port, family, type, proto, flags):\n               ^^^^^^^^^^^^^^^^^^^^^^^^^^^^^^^^^^^^^^^^^^^^^^^^^^^^^^^^^^^\nsocket.gaierror: [Errno 11001] getaddrinfo failed\n\nDuring handling of the above exception, another exception occurred:\n\nTraceback (most recent call last):\n  File \"D:\\Desktop\\python projects\\AlgoFoxLadderStrategy\\.venv\\Lib\\site-packages\\websocket\\_app.py\", line 412, in setSock\n    self.sock.connect(\n  File \"D:\\Desktop\\python projects\\AlgoFoxLadderStrategy\\.venv\\Lib\\site-packages\\websocket\\_core.py\", line 249, in connect\n    self.sock, addrs = connect(url, self.sock_opt, proxy_info(**options),\n                       ^^^^^^^^^^^^^^^^^^^^^^^^^^^^^^^^^^^^^^^^^^^^^^^^^^\n  File \"D:\\Desktop\\python projects\\AlgoFoxLadderStrategy\\.venv\\Lib\\site-packages\\websocket\\_http.py\", line 122, in connect\n    addrinfo_list, need_tunnel, auth = _get_addrinfo_list(\n                                       ^^^^^^^^^^^^^^^^^^^\n  File \"D:\\Desktop\\python projects\\AlgoFoxLadderStrategy\\.venv\\Lib\\site-packages\\websocket\\_http.py\", line 167, in _get_addrinfo_list\n    raise WebSocketAddressException(e)\nwebsocket._exceptions.WebSocketAddressException: [Errno 11001] getaddrinfo failed\n\nDuring handling of the above exception, another exception occurred:\n\nTraceback (most recent call last):\n  File \"D:\\Desktop\\python projects\\AlgoFoxLadderStrategy\\.venv\\Lib\\site-packages\\urllib3\\connection.py\", line 199, in _new_conn\n    sock = connection.create_connection(\n           ^^^^^^^^^^^^^^^^^^^^^^^^^^^^^\n  File \"D:\\Desktop\\python projects\\AlgoFoxLadderStrategy\\.venv\\Lib\\site-packages\\urllib3\\util\\connection.py\", line 60, in create_connection\n    for res in socket.getaddrinfo(host, port, family, socket.SOCK_STREAM):\n               ^^^^^^^^^^^^^^^^^^^^^^^^^^^^^^^^^^^^^^^^^^^^^^^^^^^^^^^^^^\n  File \"C:\\Users\\pulki\\AppData\\Local\\Programs\\Python\\Python311\\Lib\\socket.py\", line 962, in getaddrinfo\n    for res in _socket.getaddrinfo(host, port, family, type, proto, flags):\n               ^^^^^^^^^^^^^^^^^^^^^^^^^^^^^^^^^^^^^^^^^^^^^^^^^^^^^^^^^^^\nsocket.gaierror: [Errno 11001] getaddrinfo failed\n\nThe above exception was the direct cause of the following exception:\n\nTraceback (most recent call last):\n  File \"D:\\Desktop\\python projects\\AlgoFoxLadderStrategy\\.venv\\Lib\\site-packages\\urllib3\\connectionpool.py\", line 789, in urlopen\n    response = self._make_request(\n               ^^^^^^^^^^^^^^^^^^^\n  File \"D:\\Desktop\\python projects\\AlgoFoxLadderStrategy\\.venv\\Lib\\site-packages\\urllib3\\connectionpool.py\", line 490, in _make_request\n    raise new_e\n  File \"D:\\Desktop\\python projects\\AlgoFoxLadderStrategy\\.venv\\Lib\\site-packages\\urllib3\\connectionpool.py\", line 466, in _make_request\n    self._validate_conn(conn)\n  File \"D:\\Desktop\\python projects\\AlgoFoxLadderStrategy\\.venv\\Lib\\site-packages\\urllib3\\connectionpool.py\", line 1095, in _validate_conn\n    conn.connect()\n  File \"D:\\Desktop\\python projects\\AlgoFoxLadderStrategy\\.venv\\Lib\\site-packages\\urllib3\\connection.py\", line 693, in connect\n    self.sock = sock = self._new_conn()\n                       ^^^^^^^^^^^^^^^^\n  File \"D:\\Desktop\\python projects\\AlgoFoxLadderStrategy\\.venv\\Lib\\site-packages\\urllib3\\connection.py\", line 206, in _new_conn\n    raise NameResolutionError(self.host, self, e) from e\nurllib3.exceptions.NameResolutionError: <urllib3.connection.HTTPSConnection object at 0x000001C9CB0CA450>: Failed to resolve 'api-t1.fyers.in' ([Errno 11001] getaddrinfo failed)\n\nThe above exception was the direct cause of the following exception:\n\nTraceback (most recent call last):\n  File \"D:\\Desktop\\python projects\\AlgoFoxLadderStrategy\\.venv\\Lib\\site-packages\\requests\\adapters.py\", line 486, in send\n    resp = conn.urlopen(\n           ^^^^^^^^^^^^^\n  File \"D:\\Desktop\\python projects\\AlgoFoxLadderStrategy\\.venv\\Lib\\site-packages\\urllib3\\connectionpool.py\", line 843, in urlopen\n    retries = retries.increment(\n              ^^^^^^^^^^^^^^^^^^\n  File \"D:\\Desktop\\python projects\\AlgoFoxLadderStrategy\\.venv\\Lib\\site-packages\\urllib3\\util\\retry.py\", line 519, in increment\n    raise MaxRetryError(_pool, url, reason) from reason  # type: ignore[arg-type]\n    ^^^^^^^^^^^^^^^^^^^^^^^^^^^^^^^^^^^^^^^^^^^^^^^^^^^\nurllib3.exceptions.MaxRetryError: HTTPSConnectionPool(host='api-t1.fyers.in', port=443): Max retries exceeded with url: /data/symbol-token (Caused by NameResolutionError(\"<urllib3.connection.HTTPSConnection object at 0x000001C9CB0CA450>: Failed to resolve 'api-t1.fyers.in' ([Errno 11001] getaddrinfo failed)\"))\n\nDuring handling of the above exception, another exception occurred:\n\nTraceback (most recent call last):\n  File \"D:\\Desktop\\python projects\\AlgoFoxLadderStrategy\\.venv\\Lib\\site-packages\\fyers_apiv3\\FyersWebsocket\\data_ws.py\", line 63, in symbol_to_hsmtoken\n    response = requests.post(\n               ^^^^^^^^^^^^^^\n  File \"D:\\Desktop\\python projects\\AlgoFoxLadderStrategy\\.venv\\Lib\\site-packages\\requests\\api.py\", line 115, in post\n    return request(\"post\", url, data=data, json=json, **kwargs)\n           ^^^^^^^^^^^^^^^^^^^^^^^^^^^^^^^^^^^^^^^^^^^^^^^^^^^^\n  File \"D:\\Desktop\\python projects\\AlgoFoxLadderStrategy\\.venv\\Lib\\site-packages\\requests\\api.py\", line 59, in request\n    return session.request(method=method, url=url, **kwargs)\n           ^^^^^^^^^^^^^^^^^^^^^^^^^^^^^^^^^^^^^^^^^^^^^^^^^\n  File \"D:\\Desktop\\python projects\\AlgoFoxLadderStrategy\\.venv\\Lib\\site-packages\\requests\\sessions.py\", line 589, in request\n    resp = self.send(prep, **send_kwargs)\n           ^^^^^^^^^^^^^^^^^^^^^^^^^^^^^^\n  File \"D:\\Desktop\\python projects\\AlgoFoxLadderStrategy\\.venv\\Lib\\site-packages\\requests\\sessions.py\", line 703, in send\n    r = adapter.send(request, **kwargs)\n        ^^^^^^^^^^^^^^^^^^^^^^^^^^^^^^^\n  File \"D:\\Desktop\\python projects\\AlgoFoxLadderStrategy\\.venv\\Lib\\site-packages\\requests\\adapters.py\", line 519, in send\n    raise ConnectionError(e, request=request)\nrequests.exceptions.ConnectionError: HTTPSConnectionPool(host='api-t1.fyers.in', port=443): Max retries exceeded with url: /data/symbol-token (Caused by NameResolutionError(\"<urllib3.connection.HTTPSConnection object at 0x000001C9CB0CA450>: Failed to resolve 'api-t1.fyers.in' ([Errno 11001] getaddrinfo failed)\"))","exception_name":"ConnectionError"}
{"level":"ERROR","location":"[__symbol_conversion:1374] data_ws","message":"'NoneType' object is not subscriptable","timestamp":"2024-11-08 17:40:37,367+0530","service":"FyersDataSocket","exception":"Traceback (most recent call last):\n  File \"D:\\Desktop\\python projects\\AlgoFoxLadderStrategy\\.venv\\Lib\\site-packages\\websocket\\_http.py\", line 155, in _get_addrinfo_list\n    addrinfo_list = socket.getaddrinfo(\n                    ^^^^^^^^^^^^^^^^^^^\n  File \"C:\\Users\\pulki\\AppData\\Local\\Programs\\Python\\Python311\\Lib\\socket.py\", line 962, in getaddrinfo\n    for res in _socket.getaddrinfo(host, port, family, type, proto, flags):\n               ^^^^^^^^^^^^^^^^^^^^^^^^^^^^^^^^^^^^^^^^^^^^^^^^^^^^^^^^^^^\nsocket.gaierror: [Errno 11001] getaddrinfo failed\n\nDuring handling of the above exception, another exception occurred:\n\nTraceback (most recent call last):\n  File \"D:\\Desktop\\python projects\\AlgoFoxLadderStrategy\\.venv\\Lib\\site-packages\\websocket\\_app.py\", line 412, in setSock\n    self.sock.connect(\n  File \"D:\\Desktop\\python projects\\AlgoFoxLadderStrategy\\.venv\\Lib\\site-packages\\websocket\\_core.py\", line 249, in connect\n    self.sock, addrs = connect(url, self.sock_opt, proxy_info(**options),\n                       ^^^^^^^^^^^^^^^^^^^^^^^^^^^^^^^^^^^^^^^^^^^^^^^^^^\n  File \"D:\\Desktop\\python projects\\AlgoFoxLadderStrategy\\.venv\\Lib\\site-packages\\websocket\\_http.py\", line 122, in connect\n    addrinfo_list, need_tunnel, auth = _get_addrinfo_list(\n                                       ^^^^^^^^^^^^^^^^^^^\n  File \"D:\\Desktop\\python projects\\AlgoFoxLadderStrategy\\.venv\\Lib\\site-packages\\websocket\\_http.py\", line 167, in _get_addrinfo_list\n    raise WebSocketAddressException(e)\nwebsocket._exceptions.WebSocketAddressException: [Errno 11001] getaddrinfo failed\n\nDuring handling of the above exception, another exception occurred:\n\nTraceback (most recent call last):\n  File \"D:\\Desktop\\python projects\\AlgoFoxLadderStrategy\\.venv\\Lib\\site-packages\\fyers_apiv3\\FyersWebsocket\\data_ws.py\", line 1333, in __symbol_conversion\n    if symbol_value[3] != \"\":\n       ~~~~~~~~~~~~^^^\nTypeError: 'NoneType' object is not subscriptable","exception_name":"TypeError"}
{"level":"ERROR","location":"[<lambda>:1663] data_ws","message":"[Errno 11001] getaddrinfo failed","timestamp":"2024-11-08 17:40:39,943+0530","service":"FyersDataSocket"}
{"level":"ERROR","location":"[symbol_to_hsmtoken:126] data_ws","message":"HTTPSConnectionPool(host='api-t1.fyers.in', port=443): Max retries exceeded with url: /data/symbol-token (Caused by NameResolutionError(\"<urllib3.connection.HTTPSConnection object at 0x000001C9CB292190>: Failed to resolve 'api-t1.fyers.in' ([Errno 11001] getaddrinfo failed)\"))","timestamp":"2024-11-08 17:40:41,946+0530","service":"FyersDataSocket","exception":"Traceback (most recent call last):\n  File \"D:\\Desktop\\python projects\\AlgoFoxLadderStrategy\\.venv\\Lib\\site-packages\\websocket\\_http.py\", line 155, in _get_addrinfo_list\n    addrinfo_list = socket.getaddrinfo(\n                    ^^^^^^^^^^^^^^^^^^^\n  File \"C:\\Users\\pulki\\AppData\\Local\\Programs\\Python\\Python311\\Lib\\socket.py\", line 962, in getaddrinfo\n    for res in _socket.getaddrinfo(host, port, family, type, proto, flags):\n               ^^^^^^^^^^^^^^^^^^^^^^^^^^^^^^^^^^^^^^^^^^^^^^^^^^^^^^^^^^^\nsocket.gaierror: [Errno 11001] getaddrinfo failed\n\nDuring handling of the above exception, another exception occurred:\n\nTraceback (most recent call last):\n  File \"D:\\Desktop\\python projects\\AlgoFoxLadderStrategy\\.venv\\Lib\\site-packages\\websocket\\_app.py\", line 412, in setSock\n    self.sock.connect(\n  File \"D:\\Desktop\\python projects\\AlgoFoxLadderStrategy\\.venv\\Lib\\site-packages\\websocket\\_core.py\", line 249, in connect\n    self.sock, addrs = connect(url, self.sock_opt, proxy_info(**options),\n                       ^^^^^^^^^^^^^^^^^^^^^^^^^^^^^^^^^^^^^^^^^^^^^^^^^^\n  File \"D:\\Desktop\\python projects\\AlgoFoxLadderStrategy\\.venv\\Lib\\site-packages\\websocket\\_http.py\", line 122, in connect\n    addrinfo_list, need_tunnel, auth = _get_addrinfo_list(\n                                       ^^^^^^^^^^^^^^^^^^^\n  File \"D:\\Desktop\\python projects\\AlgoFoxLadderStrategy\\.venv\\Lib\\site-packages\\websocket\\_http.py\", line 167, in _get_addrinfo_list\n    raise WebSocketAddressException(e)\nwebsocket._exceptions.WebSocketAddressException: [Errno 11001] getaddrinfo failed\n\nDuring handling of the above exception, another exception occurred:\n\nTraceback (most recent call last):\n  File \"D:\\Desktop\\python projects\\AlgoFoxLadderStrategy\\.venv\\Lib\\site-packages\\urllib3\\connection.py\", line 199, in _new_conn\n    sock = connection.create_connection(\n           ^^^^^^^^^^^^^^^^^^^^^^^^^^^^^\n  File \"D:\\Desktop\\python projects\\AlgoFoxLadderStrategy\\.venv\\Lib\\site-packages\\urllib3\\util\\connection.py\", line 60, in create_connection\n    for res in socket.getaddrinfo(host, port, family, socket.SOCK_STREAM):\n               ^^^^^^^^^^^^^^^^^^^^^^^^^^^^^^^^^^^^^^^^^^^^^^^^^^^^^^^^^^\n  File \"C:\\Users\\pulki\\AppData\\Local\\Programs\\Python\\Python311\\Lib\\socket.py\", line 962, in getaddrinfo\n    for res in _socket.getaddrinfo(host, port, family, type, proto, flags):\n               ^^^^^^^^^^^^^^^^^^^^^^^^^^^^^^^^^^^^^^^^^^^^^^^^^^^^^^^^^^^\nsocket.gaierror: [Errno 11001] getaddrinfo failed\n\nThe above exception was the direct cause of the following exception:\n\nTraceback (most recent call last):\n  File \"D:\\Desktop\\python projects\\AlgoFoxLadderStrategy\\.venv\\Lib\\site-packages\\urllib3\\connectionpool.py\", line 789, in urlopen\n    response = self._make_request(\n               ^^^^^^^^^^^^^^^^^^^\n  File \"D:\\Desktop\\python projects\\AlgoFoxLadderStrategy\\.venv\\Lib\\site-packages\\urllib3\\connectionpool.py\", line 490, in _make_request\n    raise new_e\n  File \"D:\\Desktop\\python projects\\AlgoFoxLadderStrategy\\.venv\\Lib\\site-packages\\urllib3\\connectionpool.py\", line 466, in _make_request\n    self._validate_conn(conn)\n  File \"D:\\Desktop\\python projects\\AlgoFoxLadderStrategy\\.venv\\Lib\\site-packages\\urllib3\\connectionpool.py\", line 1095, in _validate_conn\n    conn.connect()\n  File \"D:\\Desktop\\python projects\\AlgoFoxLadderStrategy\\.venv\\Lib\\site-packages\\urllib3\\connection.py\", line 693, in connect\n    self.sock = sock = self._new_conn()\n                       ^^^^^^^^^^^^^^^^\n  File \"D:\\Desktop\\python projects\\AlgoFoxLadderStrategy\\.venv\\Lib\\site-packages\\urllib3\\connection.py\", line 206, in _new_conn\n    raise NameResolutionError(self.host, self, e) from e\nurllib3.exceptions.NameResolutionError: <urllib3.connection.HTTPSConnection object at 0x000001C9CB292190>: Failed to resolve 'api-t1.fyers.in' ([Errno 11001] getaddrinfo failed)\n\nThe above exception was the direct cause of the following exception:\n\nTraceback (most recent call last):\n  File \"D:\\Desktop\\python projects\\AlgoFoxLadderStrategy\\.venv\\Lib\\site-packages\\requests\\adapters.py\", line 486, in send\n    resp = conn.urlopen(\n           ^^^^^^^^^^^^^\n  File \"D:\\Desktop\\python projects\\AlgoFoxLadderStrategy\\.venv\\Lib\\site-packages\\urllib3\\connectionpool.py\", line 843, in urlopen\n    retries = retries.increment(\n              ^^^^^^^^^^^^^^^^^^\n  File \"D:\\Desktop\\python projects\\AlgoFoxLadderStrategy\\.venv\\Lib\\site-packages\\urllib3\\util\\retry.py\", line 519, in increment\n    raise MaxRetryError(_pool, url, reason) from reason  # type: ignore[arg-type]\n    ^^^^^^^^^^^^^^^^^^^^^^^^^^^^^^^^^^^^^^^^^^^^^^^^^^^\nurllib3.exceptions.MaxRetryError: HTTPSConnectionPool(host='api-t1.fyers.in', port=443): Max retries exceeded with url: /data/symbol-token (Caused by NameResolutionError(\"<urllib3.connection.HTTPSConnection object at 0x000001C9CB292190>: Failed to resolve 'api-t1.fyers.in' ([Errno 11001] getaddrinfo failed)\"))\n\nDuring handling of the above exception, another exception occurred:\n\nTraceback (most recent call last):\n  File \"D:\\Desktop\\python projects\\AlgoFoxLadderStrategy\\.venv\\Lib\\site-packages\\fyers_apiv3\\FyersWebsocket\\data_ws.py\", line 63, in symbol_to_hsmtoken\n    response = requests.post(\n               ^^^^^^^^^^^^^^\n  File \"D:\\Desktop\\python projects\\AlgoFoxLadderStrategy\\.venv\\Lib\\site-packages\\requests\\api.py\", line 115, in post\n    return request(\"post\", url, data=data, json=json, **kwargs)\n           ^^^^^^^^^^^^^^^^^^^^^^^^^^^^^^^^^^^^^^^^^^^^^^^^^^^^\n  File \"D:\\Desktop\\python projects\\AlgoFoxLadderStrategy\\.venv\\Lib\\site-packages\\requests\\api.py\", line 59, in request\n    return session.request(method=method, url=url, **kwargs)\n           ^^^^^^^^^^^^^^^^^^^^^^^^^^^^^^^^^^^^^^^^^^^^^^^^^\n  File \"D:\\Desktop\\python projects\\AlgoFoxLadderStrategy\\.venv\\Lib\\site-packages\\requests\\sessions.py\", line 589, in request\n    resp = self.send(prep, **send_kwargs)\n           ^^^^^^^^^^^^^^^^^^^^^^^^^^^^^^\n  File \"D:\\Desktop\\python projects\\AlgoFoxLadderStrategy\\.venv\\Lib\\site-packages\\requests\\sessions.py\", line 703, in send\n    r = adapter.send(request, **kwargs)\n        ^^^^^^^^^^^^^^^^^^^^^^^^^^^^^^^\n  File \"D:\\Desktop\\python projects\\AlgoFoxLadderStrategy\\.venv\\Lib\\site-packages\\requests\\adapters.py\", line 519, in send\n    raise ConnectionError(e, request=request)\nrequests.exceptions.ConnectionError: HTTPSConnectionPool(host='api-t1.fyers.in', port=443): Max retries exceeded with url: /data/symbol-token (Caused by NameResolutionError(\"<urllib3.connection.HTTPSConnection object at 0x000001C9CB292190>: Failed to resolve 'api-t1.fyers.in' ([Errno 11001] getaddrinfo failed)\"))","exception_name":"ConnectionError"}
{"level":"ERROR","location":"[__symbol_conversion:1374] data_ws","message":"'NoneType' object is not subscriptable","timestamp":"2024-11-08 17:40:41,953+0530","service":"FyersDataSocket","exception":"Traceback (most recent call last):\n  File \"D:\\Desktop\\python projects\\AlgoFoxLadderStrategy\\.venv\\Lib\\site-packages\\websocket\\_http.py\", line 155, in _get_addrinfo_list\n    addrinfo_list = socket.getaddrinfo(\n                    ^^^^^^^^^^^^^^^^^^^\n  File \"C:\\Users\\pulki\\AppData\\Local\\Programs\\Python\\Python311\\Lib\\socket.py\", line 962, in getaddrinfo\n    for res in _socket.getaddrinfo(host, port, family, type, proto, flags):\n               ^^^^^^^^^^^^^^^^^^^^^^^^^^^^^^^^^^^^^^^^^^^^^^^^^^^^^^^^^^^\nsocket.gaierror: [Errno 11001] getaddrinfo failed\n\nDuring handling of the above exception, another exception occurred:\n\nTraceback (most recent call last):\n  File \"D:\\Desktop\\python projects\\AlgoFoxLadderStrategy\\.venv\\Lib\\site-packages\\websocket\\_app.py\", line 412, in setSock\n    self.sock.connect(\n  File \"D:\\Desktop\\python projects\\AlgoFoxLadderStrategy\\.venv\\Lib\\site-packages\\websocket\\_core.py\", line 249, in connect\n    self.sock, addrs = connect(url, self.sock_opt, proxy_info(**options),\n                       ^^^^^^^^^^^^^^^^^^^^^^^^^^^^^^^^^^^^^^^^^^^^^^^^^^\n  File \"D:\\Desktop\\python projects\\AlgoFoxLadderStrategy\\.venv\\Lib\\site-packages\\websocket\\_http.py\", line 122, in connect\n    addrinfo_list, need_tunnel, auth = _get_addrinfo_list(\n                                       ^^^^^^^^^^^^^^^^^^^\n  File \"D:\\Desktop\\python projects\\AlgoFoxLadderStrategy\\.venv\\Lib\\site-packages\\websocket\\_http.py\", line 167, in _get_addrinfo_list\n    raise WebSocketAddressException(e)\nwebsocket._exceptions.WebSocketAddressException: [Errno 11001] getaddrinfo failed\n\nDuring handling of the above exception, another exception occurred:\n\nTraceback (most recent call last):\n  File \"D:\\Desktop\\python projects\\AlgoFoxLadderStrategy\\.venv\\Lib\\site-packages\\fyers_apiv3\\FyersWebsocket\\data_ws.py\", line 1333, in __symbol_conversion\n    if symbol_value[3] != \"\":\n       ~~~~~~~~~~~~^^^\nTypeError: 'NoneType' object is not subscriptable","exception_name":"TypeError"}
